2020-06-10 20:55:14,788 ERROR: Exception on /reset_password_request [POST] [in /home/daomaster/Desktop/venv/venv/lib/python3.7/site-packages/flask/app.py:1892]
Traceback (most recent call last):
  File "/home/daomaster/Desktop/venv/venv/lib/python3.7/site-packages/flask/app.py", line 2447, in wsgi_app
    response = self.full_dispatch_request()
  File "/home/daomaster/Desktop/venv/venv/lib/python3.7/site-packages/flask/app.py", line 1952, in full_dispatch_request
    rv = self.handle_user_exception(e)
  File "/home/daomaster/Desktop/venv/venv/lib/python3.7/site-packages/flask/app.py", line 1821, in handle_user_exception
    reraise(exc_type, exc_value, tb)
  File "/home/daomaster/Desktop/venv/venv/lib/python3.7/site-packages/flask/_compat.py", line 39, in reraise
    raise value
  File "/home/daomaster/Desktop/venv/venv/lib/python3.7/site-packages/flask/app.py", line 1950, in full_dispatch_request
    rv = self.dispatch_request()
  File "/home/daomaster/Desktop/venv/venv/lib/python3.7/site-packages/flask/app.py", line 1936, in dispatch_request
    return self.view_functions[rule.endpoint](**req.view_args)
  File "/home/daomaster/Desktop/venv/miguel_flask/app/routes.py", line 171, in reset_password_request
    send_password_reset_email(user)
  File "/home/daomaster/Desktop/venv/miguel_flask/app/email.py", line 15, in send_password_reset_email
    token = user.get_reset_password_token()
AttributeError: 'User' object has no attribute 'get_reset_password_token'
2020-06-10 20:55:41,614 INFO: Microblog startup [in /home/daomaster/Desktop/venv/miguel_flask/app/__init__.py:51]
2020-06-10 20:55:42,914 ERROR: Exception on /reset_password_request [POST] [in /home/daomaster/Desktop/venv/venv/lib/python3.7/site-packages/flask/app.py:1892]
Traceback (most recent call last):
  File "/home/daomaster/Desktop/venv/venv/lib/python3.7/site-packages/flask/app.py", line 2447, in wsgi_app
    response = self.full_dispatch_request()
  File "/home/daomaster/Desktop/venv/venv/lib/python3.7/site-packages/flask/app.py", line 1952, in full_dispatch_request
    rv = self.handle_user_exception(e)
  File "/home/daomaster/Desktop/venv/venv/lib/python3.7/site-packages/flask/app.py", line 1821, in handle_user_exception
    reraise(exc_type, exc_value, tb)
  File "/home/daomaster/Desktop/venv/venv/lib/python3.7/site-packages/flask/_compat.py", line 39, in reraise
    raise value
  File "/home/daomaster/Desktop/venv/venv/lib/python3.7/site-packages/flask/app.py", line 1950, in full_dispatch_request
    rv = self.dispatch_request()
  File "/home/daomaster/Desktop/venv/venv/lib/python3.7/site-packages/flask/app.py", line 1936, in dispatch_request
    return self.view_functions[rule.endpoint](**req.view_args)
  File "/home/daomaster/Desktop/venv/miguel_flask/app/routes.py", line 171, in reset_password_request
    send_password_reset_email(user)
  File "/home/daomaster/Desktop/venv/miguel_flask/app/email.py", line 15, in send_password_reset_email
    token = user.get_reset_password_token()
  File "/home/daomaster/Desktop/venv/miguel_flask/app/models.py", line 66, in get_reset_password_token
    return jwt.encode(
NameError: name 'jwt' is not defined
2020-06-10 20:55:55,866 INFO: Microblog startup [in /home/daomaster/Desktop/venv/miguel_flask/app/__init__.py:51]
2020-06-10 20:56:07,994 ERROR: Exception on /reset_password_request [POST] [in /home/daomaster/Desktop/venv/venv/lib/python3.7/site-packages/flask/app.py:1892]
Traceback (most recent call last):
  File "/home/daomaster/Desktop/venv/venv/lib/python3.7/site-packages/flask/app.py", line 2447, in wsgi_app
    response = self.full_dispatch_request()
  File "/home/daomaster/Desktop/venv/venv/lib/python3.7/site-packages/flask/app.py", line 1952, in full_dispatch_request
    rv = self.handle_user_exception(e)
  File "/home/daomaster/Desktop/venv/venv/lib/python3.7/site-packages/flask/app.py", line 1821, in handle_user_exception
    reraise(exc_type, exc_value, tb)
  File "/home/daomaster/Desktop/venv/venv/lib/python3.7/site-packages/flask/_compat.py", line 39, in reraise
    raise value
  File "/home/daomaster/Desktop/venv/venv/lib/python3.7/site-packages/flask/app.py", line 1950, in full_dispatch_request
    rv = self.dispatch_request()
  File "/home/daomaster/Desktop/venv/venv/lib/python3.7/site-packages/flask/app.py", line 1936, in dispatch_request
    return self.view_functions[rule.endpoint](**req.view_args)
  File "/home/daomaster/Desktop/venv/miguel_flask/app/routes.py", line 171, in reset_password_request
    send_password_reset_email(user)
  File "/home/daomaster/Desktop/venv/miguel_flask/app/email.py", line 15, in send_password_reset_email
    token = user.get_reset_password_token()
  File "/home/daomaster/Desktop/venv/miguel_flask/app/models.py", line 66, in get_reset_password_token
    return jwt.encode(
NameError: name 'jwt' is not defined
2020-06-10 20:56:28,520 INFO: Microblog startup [in /home/daomaster/Desktop/venv/miguel_flask/app/__init__.py:51]
2020-06-10 20:56:40,429 ERROR: Exception on /reset_password_request [POST] [in /home/daomaster/Desktop/venv/venv/lib/python3.7/site-packages/flask/app.py:1892]
Traceback (most recent call last):
  File "/home/daomaster/Desktop/venv/venv/lib/python3.7/site-packages/flask/app.py", line 2447, in wsgi_app
    response = self.full_dispatch_request()
  File "/home/daomaster/Desktop/venv/venv/lib/python3.7/site-packages/flask/app.py", line 1952, in full_dispatch_request
    rv = self.handle_user_exception(e)
  File "/home/daomaster/Desktop/venv/venv/lib/python3.7/site-packages/flask/app.py", line 1821, in handle_user_exception
    reraise(exc_type, exc_value, tb)
  File "/home/daomaster/Desktop/venv/venv/lib/python3.7/site-packages/flask/_compat.py", line 39, in reraise
    raise value
  File "/home/daomaster/Desktop/venv/venv/lib/python3.7/site-packages/flask/app.py", line 1950, in full_dispatch_request
    rv = self.dispatch_request()
  File "/home/daomaster/Desktop/venv/venv/lib/python3.7/site-packages/flask/app.py", line 1936, in dispatch_request
    return self.view_functions[rule.endpoint](**req.view_args)
  File "/home/daomaster/Desktop/venv/miguel_flask/app/routes.py", line 171, in reset_password_request
    send_password_reset_email(user)
  File "/home/daomaster/Desktop/venv/miguel_flask/app/email.py", line 15, in send_password_reset_email
    token = user.get_reset_password_token()
  File "/home/daomaster/Desktop/venv/miguel_flask/app/models.py", line 68, in get_reset_password_token
    {'reset_password': self.id, 'exp': time() + expires_in},
NameError: name 'time' is not defined
2020-06-10 20:56:52,426 INFO: Microblog startup [in /home/daomaster/Desktop/venv/miguel_flask/app/__init__.py:51]
2020-06-10 20:57:00,193 ERROR: Exception on /reset_password_request [POST] [in /home/daomaster/Desktop/venv/venv/lib/python3.7/site-packages/flask/app.py:1892]
Traceback (most recent call last):
  File "/home/daomaster/Desktop/venv/venv/lib/python3.7/site-packages/flask/app.py", line 2447, in wsgi_app
    response = self.full_dispatch_request()
  File "/home/daomaster/Desktop/venv/venv/lib/python3.7/site-packages/flask/app.py", line 1952, in full_dispatch_request
    rv = self.handle_user_exception(e)
  File "/home/daomaster/Desktop/venv/venv/lib/python3.7/site-packages/flask/app.py", line 1821, in handle_user_exception
    reraise(exc_type, exc_value, tb)
  File "/home/daomaster/Desktop/venv/venv/lib/python3.7/site-packages/flask/_compat.py", line 39, in reraise
    raise value
  File "/home/daomaster/Desktop/venv/venv/lib/python3.7/site-packages/flask/app.py", line 1950, in full_dispatch_request
    rv = self.dispatch_request()
  File "/home/daomaster/Desktop/venv/venv/lib/python3.7/site-packages/flask/app.py", line 1936, in dispatch_request
    return self.view_functions[rule.endpoint](**req.view_args)
  File "/home/daomaster/Desktop/venv/miguel_flask/app/routes.py", line 171, in reset_password_request
    send_password_reset_email(user)
  File "/home/daomaster/Desktop/venv/miguel_flask/app/email.py", line 15, in send_password_reset_email
    token = user.get_reset_password_token()
  File "/home/daomaster/Desktop/venv/miguel_flask/app/models.py", line 69, in get_reset_password_token
    {'reset_password': self.id, 'exp': time() + expires_in},
TypeError: 'module' object is not callable
2020-06-10 20:58:22,745 INFO: Microblog startup [in /home/daomaster/Desktop/venv/miguel_flask/app/__init__.py:51]
2020-06-10 20:58:33,042 ERROR: Exception on /reset_password_request [POST] [in /home/daomaster/Desktop/venv/venv/lib/python3.7/site-packages/flask/app.py:1892]
Traceback (most recent call last):
  File "/home/daomaster/Desktop/venv/venv/lib/python3.7/site-packages/flask/app.py", line 2447, in wsgi_app
    response = self.full_dispatch_request()
  File "/home/daomaster/Desktop/venv/venv/lib/python3.7/site-packages/flask/app.py", line 1952, in full_dispatch_request
    rv = self.handle_user_exception(e)
  File "/home/daomaster/Desktop/venv/venv/lib/python3.7/site-packages/flask/app.py", line 1821, in handle_user_exception
    reraise(exc_type, exc_value, tb)
  File "/home/daomaster/Desktop/venv/venv/lib/python3.7/site-packages/flask/_compat.py", line 39, in reraise
    raise value
  File "/home/daomaster/Desktop/venv/venv/lib/python3.7/site-packages/flask/app.py", line 1950, in full_dispatch_request
    rv = self.dispatch_request()
  File "/home/daomaster/Desktop/venv/venv/lib/python3.7/site-packages/flask/app.py", line 1936, in dispatch_request
    return self.view_functions[rule.endpoint](**req.view_args)
  File "/home/daomaster/Desktop/venv/miguel_flask/app/routes.py", line 171, in reset_password_request
    send_password_reset_email(user)
  File "/home/daomaster/Desktop/venv/miguel_flask/app/email.py", line 15, in send_password_reset_email
    token = user.get_reset_password_token()
  File "/home/daomaster/Desktop/venv/miguel_flask/app/models.py", line 70, in get_reset_password_token
    app.config['SECRET_KEY'], algorithm='HS256').decode('utf-8')
NameError: name 'app' is not defined
2020-06-10 20:59:34,514 INFO: Microblog startup [in /home/daomaster/Desktop/venv/miguel_flask/app/__init__.py:51]
