2020-06-10 07:21:42,277 ERROR: Exception on /login [GET] [in /home/daomaster/Desktop/venv/venv/lib/python3.7/site-packages/flask/app.py:1892]
Traceback (most recent call last):
  File "/home/daomaster/Desktop/venv/venv/lib/python3.7/site-packages/flask/app.py", line 2447, in wsgi_app
    response = self.full_dispatch_request()
  File "/home/daomaster/Desktop/venv/venv/lib/python3.7/site-packages/flask/app.py", line 1952, in full_dispatch_request
    rv = self.handle_user_exception(e)
  File "/home/daomaster/Desktop/venv/venv/lib/python3.7/site-packages/flask/app.py", line 1821, in handle_user_exception
    reraise(exc_type, exc_value, tb)
  File "/home/daomaster/Desktop/venv/venv/lib/python3.7/site-packages/flask/_compat.py", line 39, in reraise
    raise value
  File "/home/daomaster/Desktop/venv/venv/lib/python3.7/site-packages/flask/app.py", line 1950, in full_dispatch_request
    rv = self.dispatch_request()
  File "/home/daomaster/Desktop/venv/venv/lib/python3.7/site-packages/flask/app.py", line 1936, in dispatch_request
    return self.view_functions[rule.endpoint](**req.view_args)
  File "/home/daomaster/Desktop/venv/miguel_flask/app/routes.py", line 86, in login
    return render_template('login.html', title='Sign In', form=form)
  File "/home/daomaster/Desktop/venv/venv/lib/python3.7/site-packages/flask/templating.py", line 140, in render_template
    ctx.app,
  File "/home/daomaster/Desktop/venv/venv/lib/python3.7/site-packages/flask/templating.py", line 120, in _render
    rv = template.render(context)
  File "/home/daomaster/Desktop/venv/venv/lib/python3.7/site-packages/jinja2/environment.py", line 1090, in render
    self.environment.handle_exception()
  File "/home/daomaster/Desktop/venv/venv/lib/python3.7/site-packages/jinja2/environment.py", line 832, in handle_exception
    reraise(*rewrite_traceback_stack(source=source))
  File "/home/daomaster/Desktop/venv/venv/lib/python3.7/site-packages/jinja2/_compat.py", line 28, in reraise
    raise value.with_traceback(tb)
  File "/home/daomaster/Desktop/venv/miguel_flask/app/templates/login.html", line 1, in top-level template code
    {% extends "base.html" %} {% block content %}
  File "/home/daomaster/Desktop/venv/venv/lib/python3.7/site-packages/jinja2/environment.py", line 832, in handle_exception
    reraise(*rewrite_traceback_stack(source=source))
  File "/home/daomaster/Desktop/venv/venv/lib/python3.7/site-packages/jinja2/_compat.py", line 28, in reraise
    raise value.with_traceback(tb)
  File "/home/daomaster/Desktop/venv/miguel_flask/app/templates/base.html", line 48, in template
    {% endif %} {% endwith %} {% block content %}{% endblock %}
jinja2.exceptions.TemplateAssertionError: block 'content' defined twice
2020-06-10 07:22:42,158 INFO: Microblog startup [in /home/daomaster/Desktop/venv/miguel_flask/app/__init__.py:45]
2020-06-10 07:33:14,781 INFO: Microblog startup [in /home/daomaster/Desktop/venv/miguel_flask/app/__init__.py:45]
2020-06-10 07:39:16,036 INFO: Microblog startup [in /home/daomaster/Desktop/venv/miguel_flask/app/__init__.py:45]
2020-06-10 07:41:58,407 INFO: Microblog startup [in /home/daomaster/Desktop/venv/miguel_flask/app/__init__.py:45]
